2024-05-05 23:13:54,202 ERROR: Unhandled exception [in /home/rzu/microblog/app/tasks.py:54]
Traceback (most recent call last):
  File "/home/rzu/microblog/app/tasks.py", line 44, in export_posts
    send_email(
  File "/home/rzu/microblog/app/email.py", line 21, in send_email
    mail.send(msg)
  File "/home/rzu/.local/share/virtualenvs/microblog-oeRwd4YA/lib/python3.11/site-packages/flask_mail.py", line 491, in send
    with self.connect() as connection:
  File "/home/rzu/.local/share/virtualenvs/microblog-oeRwd4YA/lib/python3.11/site-packages/flask_mail.py", line 144, in __enter__
    self.host = self.configure_host()
                ^^^^^^^^^^^^^^^^^^^^^
  File "/home/rzu/.local/share/virtualenvs/microblog-oeRwd4YA/lib/python3.11/site-packages/flask_mail.py", line 158, in configure_host
    host = smtplib.SMTP(self.mail.server, self.mail.port)
           ^^^^^^^^^^^^^^^^^^^^^^^^^^^^^^^^^^^^^^^^^^^^^^
  File "/home/rzu/.pyenv/versions/3.11.9/lib/python3.11/smtplib.py", line 255, in __init__
    (code, msg) = self.connect(host, port)
                  ^^^^^^^^^^^^^^^^^^^^^^^^
  File "/home/rzu/.pyenv/versions/3.11.9/lib/python3.11/smtplib.py", line 341, in connect
    self.sock = self._get_socket(host, port, self.timeout)
                ^^^^^^^^^^^^^^^^^^^^^^^^^^^^^^^^^^^^^^^^^^
  File "/home/rzu/.pyenv/versions/3.11.9/lib/python3.11/smtplib.py", line 312, in _get_socket
    return socket.create_connection((host, port), timeout,
           ^^^^^^^^^^^^^^^^^^^^^^^^^^^^^^^^^^^^^^^^^^^^^^^
  File "/home/rzu/.pyenv/versions/3.11.9/lib/python3.11/socket.py", line 851, in create_connection
    raise exceptions[0]
  File "/home/rzu/.pyenv/versions/3.11.9/lib/python3.11/socket.py", line 836, in create_connection
    sock.connect(sa)
ConnectionRefusedError: [Errno 111] Connection refused
2024-05-05 23:17:42,126 INFO: Microblog startup [in /home/rzu/microblog/app/__init__.py:92]
2024-05-05 23:17:57,618 ERROR: Unhandled exception [in /home/rzu/microblog/app/tasks.py:54]
Traceback (most recent call last):
  File "/home/rzu/microblog/app/tasks.py", line 44, in export_posts
    send_email(
  File "/home/rzu/microblog/app/email.py", line 21, in send_email
    mail.send(msg)
  File "/home/rzu/.local/share/virtualenvs/microblog-oeRwd4YA/lib/python3.11/site-packages/flask_mail.py", line 491, in send
    with self.connect() as connection:
  File "/home/rzu/.local/share/virtualenvs/microblog-oeRwd4YA/lib/python3.11/site-packages/flask_mail.py", line 144, in __enter__
    self.host = self.configure_host()
                ^^^^^^^^^^^^^^^^^^^^^
  File "/home/rzu/.local/share/virtualenvs/microblog-oeRwd4YA/lib/python3.11/site-packages/flask_mail.py", line 158, in configure_host
    host = smtplib.SMTP(self.mail.server, self.mail.port)
           ^^^^^^^^^^^^^^^^^^^^^^^^^^^^^^^^^^^^^^^^^^^^^^
  File "/home/rzu/.pyenv/versions/3.11.9/lib/python3.11/smtplib.py", line 255, in __init__
    (code, msg) = self.connect(host, port)
                  ^^^^^^^^^^^^^^^^^^^^^^^^
  File "/home/rzu/.pyenv/versions/3.11.9/lib/python3.11/smtplib.py", line 341, in connect
    self.sock = self._get_socket(host, port, self.timeout)
                ^^^^^^^^^^^^^^^^^^^^^^^^^^^^^^^^^^^^^^^^^^
  File "/home/rzu/.pyenv/versions/3.11.9/lib/python3.11/smtplib.py", line 312, in _get_socket
    return socket.create_connection((host, port), timeout,
           ^^^^^^^^^^^^^^^^^^^^^^^^^^^^^^^^^^^^^^^^^^^^^^^
  File "/home/rzu/.pyenv/versions/3.11.9/lib/python3.11/socket.py", line 851, in create_connection
    raise exceptions[0]
  File "/home/rzu/.pyenv/versions/3.11.9/lib/python3.11/socket.py", line 836, in create_connection
    sock.connect(sa)
ConnectionRefusedError: [Errno 111] Connection refused
2024-05-05 23:20:22,716 INFO: Microblog startup [in /home/rzu/microblog/app/__init__.py:92]
2024-05-05 23:20:43,021 ERROR: Unhandled exception [in /home/rzu/microblog/app/tasks.py:54]
Traceback (most recent call last):
  File "/home/rzu/microblog/app/tasks.py", line 44, in export_posts
    send_email(
  File "/home/rzu/microblog/app/email.py", line 24, in send_email
    mail.send(msg)
  File "/home/rzu/.local/share/virtualenvs/microblog-oeRwd4YA/lib/python3.11/site-packages/flask_mail.py", line 491, in send
    with self.connect() as connection:
  File "/home/rzu/.local/share/virtualenvs/microblog-oeRwd4YA/lib/python3.11/site-packages/flask_mail.py", line 144, in __enter__
    self.host = self.configure_host()
                ^^^^^^^^^^^^^^^^^^^^^
  File "/home/rzu/.local/share/virtualenvs/microblog-oeRwd4YA/lib/python3.11/site-packages/flask_mail.py", line 158, in configure_host
    host = smtplib.SMTP(self.mail.server, self.mail.port)
           ^^^^^^^^^^^^^^^^^^^^^^^^^^^^^^^^^^^^^^^^^^^^^^
  File "/home/rzu/.pyenv/versions/3.11.9/lib/python3.11/smtplib.py", line 255, in __init__
    (code, msg) = self.connect(host, port)
                  ^^^^^^^^^^^^^^^^^^^^^^^^
  File "/home/rzu/.pyenv/versions/3.11.9/lib/python3.11/smtplib.py", line 341, in connect
    self.sock = self._get_socket(host, port, self.timeout)
                ^^^^^^^^^^^^^^^^^^^^^^^^^^^^^^^^^^^^^^^^^^
  File "/home/rzu/.pyenv/versions/3.11.9/lib/python3.11/smtplib.py", line 312, in _get_socket
    return socket.create_connection((host, port), timeout,
           ^^^^^^^^^^^^^^^^^^^^^^^^^^^^^^^^^^^^^^^^^^^^^^^
  File "/home/rzu/.pyenv/versions/3.11.9/lib/python3.11/socket.py", line 851, in create_connection
    raise exceptions[0]
  File "/home/rzu/.pyenv/versions/3.11.9/lib/python3.11/socket.py", line 836, in create_connection
    sock.connect(sa)
ConnectionRefusedError: [Errno 111] Connection refused
2024-05-07 21:17:13,407 INFO: Microblog startup [in /home/rzu/microblog/app/__init__.py:91]
2024-05-07 21:17:48,675 ERROR: Unhandled exception [in /home/rzu/microblog/app/tasks.py:54]
Traceback (most recent call last):
  File "/home/rzu/microblog/app/tasks.py", line 44, in export_posts
    send_email(
  File "/home/rzu/microblog/app/email.py", line 25, in send_email
    mail.send(msg)
  File "/home/rzu/.local/share/virtualenvs/microblog-oeRwd4YA/lib/python3.11/site-packages/flask_mail.py", line 491, in send
    with self.connect() as connection:
  File "/home/rzu/.local/share/virtualenvs/microblog-oeRwd4YA/lib/python3.11/site-packages/flask_mail.py", line 144, in __enter__
    self.host = self.configure_host()
                ^^^^^^^^^^^^^^^^^^^^^
  File "/home/rzu/.local/share/virtualenvs/microblog-oeRwd4YA/lib/python3.11/site-packages/flask_mail.py", line 158, in configure_host
    host = smtplib.SMTP(self.mail.server, self.mail.port)
           ^^^^^^^^^^^^^^^^^^^^^^^^^^^^^^^^^^^^^^^^^^^^^^
  File "/home/rzu/.pyenv/versions/3.11.9/lib/python3.11/smtplib.py", line 255, in __init__
    (code, msg) = self.connect(host, port)
                  ^^^^^^^^^^^^^^^^^^^^^^^^
  File "/home/rzu/.pyenv/versions/3.11.9/lib/python3.11/smtplib.py", line 341, in connect
    self.sock = self._get_socket(host, port, self.timeout)
                ^^^^^^^^^^^^^^^^^^^^^^^^^^^^^^^^^^^^^^^^^^
  File "/home/rzu/.pyenv/versions/3.11.9/lib/python3.11/smtplib.py", line 312, in _get_socket
    return socket.create_connection((host, port), timeout,
           ^^^^^^^^^^^^^^^^^^^^^^^^^^^^^^^^^^^^^^^^^^^^^^^
  File "/home/rzu/.pyenv/versions/3.11.9/lib/python3.11/socket.py", line 851, in create_connection
    raise exceptions[0]
  File "/home/rzu/.pyenv/versions/3.11.9/lib/python3.11/socket.py", line 836, in create_connection
    sock.connect(sa)
ConnectionRefusedError: [Errno 111] Connection refused
2024-05-07 21:34:25,579 INFO: Microblog startup [in /home/rzu/microblog/app/__init__.py:91]
2024-05-07 21:34:50,761 ERROR: Unhandled exception [in /home/rzu/microblog/app/tasks.py:54]
Traceback (most recent call last):
  File "/home/rzu/microblog/app/tasks.py", line 44, in export_posts
    send_email(
  File "/home/rzu/microblog/app/email.py", line 25, in send_email
    mail.send(msg)
  File "/home/rzu/.local/share/virtualenvs/microblog-oeRwd4YA/lib/python3.11/site-packages/flask_mail.py", line 491, in send
    with self.connect() as connection:
  File "/home/rzu/.local/share/virtualenvs/microblog-oeRwd4YA/lib/python3.11/site-packages/flask_mail.py", line 144, in __enter__
    self.host = self.configure_host()
                ^^^^^^^^^^^^^^^^^^^^^
  File "/home/rzu/.local/share/virtualenvs/microblog-oeRwd4YA/lib/python3.11/site-packages/flask_mail.py", line 158, in configure_host
    host = smtplib.SMTP(self.mail.server, self.mail.port)
           ^^^^^^^^^^^^^^^^^^^^^^^^^^^^^^^^^^^^^^^^^^^^^^
  File "/home/rzu/.pyenv/versions/3.11.9/lib/python3.11/smtplib.py", line 255, in __init__
    (code, msg) = self.connect(host, port)
                  ^^^^^^^^^^^^^^^^^^^^^^^^
  File "/home/rzu/.pyenv/versions/3.11.9/lib/python3.11/smtplib.py", line 341, in connect
    self.sock = self._get_socket(host, port, self.timeout)
                ^^^^^^^^^^^^^^^^^^^^^^^^^^^^^^^^^^^^^^^^^^
  File "/home/rzu/.pyenv/versions/3.11.9/lib/python3.11/smtplib.py", line 312, in _get_socket
    return socket.create_connection((host, port), timeout,
           ^^^^^^^^^^^^^^^^^^^^^^^^^^^^^^^^^^^^^^^^^^^^^^^
  File "/home/rzu/.pyenv/versions/3.11.9/lib/python3.11/socket.py", line 851, in create_connection
    raise exceptions[0]
  File "/home/rzu/.pyenv/versions/3.11.9/lib/python3.11/socket.py", line 836, in create_connection
    sock.connect(sa)
ConnectionRefusedError: [Errno 111] Connection refused
2024-05-07 21:39:49,537 INFO: Microblog startup [in /home/rzu/microblog/app/__init__.py:91]
